Workbook

Sheet EXP lvls
A1: Star | B1: EXP to TOP lvl | D1: Level | E1: 1* | F1: 2* | G1: 3* | H1: 4* | I1: 5* | J1: 6* | S1: Buffed | T1: Cost | U1: Burned | V1: XP Gain | W1: Cost to max | X1: Evolve | Y1: Xp/Mana | Z1: Nbr needed
A2: 1 | B2: 15120 | D2: 1 | E2: 460 | F2: 552 | G2: 662 | H2: 796 | I2: 952 | J2: 1150 | L2: Kolumna1 | M2: Missing | N2: Done | O2: Zapas | P2: XP to gain | Q2: Mana Cost | T2: 1* | U2: 150 | V2: 1* | W2: =Tabela3[[#This Row],[2*]]+0.401*F3 -> 800.219 | X2: =$U2*$B$2/$W2 -> 2834.2241 | Y2: 1600 | Z2: =W2/U2 -> 5.3347933 | AA2: =$B$2/W2 -> 18.894828
A3: 2 | B3: 35822 | D3: 2 | E3: 516 | F3: 619 | G3: 743 | H3: 892 | I3: 1068 | J3: 1290 | L3: piątki 1 | M3: =5-Tabela6[[#This Row],[Done]] -> 1 | N3: 4 | O3: 0 | P3: 0 | Q3: =Tabela6[[#This Row],[Missing]]*22300 -> 22300 | R3: 2 | T3: 2* | U3: 500 | V3: 2* | W3: =F2+Tabela3[[#This Row],[2*]]+0.847*F4 -> 1759.665 | X3: =$U3*$B$3/$W3 -> 10178.642 | Y3: 4000 | Z3: =W3/U3 -> 3.51933 | AA3: =$B$3/W3 -> 20.357284
A4: 3 | B4: 82182 | D4: 3 | E4: 579 | F4: 695 | G4: 834 | H4: 1002 | I4: 1199 | J4: 1447 | L4: czworki full | M4: =MAXA(M3-Tabela6[[#This Row],[Done]],0) -> 0 | N4: 4 | O4: =MAXA(Tabela6[[#This Row],[Done]]-M3,0) -> 3 | P4: =M4*$B$5 -> 0 | Q4: =Tabela6[[#This Row],[Missing]]*9600 -> 0 | R4: 0 | T4: 2* | U4: 300 | V4: 1* | W4: =Tabela3[[#This Row],[2*]]+0.401*F5 -> 1007.379 | X4: =$U4*$B$3/$W4 -> 10667.882 | Y4: 4000 | Z4: =W4/U4 -> 3.35793 | AA4: =$B$3/W4 -> 35.559606
A5: 4 | B5: 189750 | D5: 4 | E5: 650 | F5: 779 | G5: 936 | H5: 1124 | I5: 1344 | J5: 1624 | L5: czworek 1 | M5: =MAXA(4*M3-Tabela6[[#This Row],[Done]],0) -> 0 | N5: 4 | O5: =MAXA(-(4*M3-Tabela6[[#This Row],[Done]])-M4,0) -> 0 | Q5: =Tabela6[[#This Row],[Missing]]*9600 -> 0 | R5: 9 | T5: 2* | U5: 500 | V5: 2* | W5: =F4+Tabela3[[#This Row],[2*]]+0.847*F6 -> 2215.125 | X5: =$U5*$B$3/$W5 -> 8085.7739 | Y5: 4000 | Z5: =W5/U5 -> 4.43025 | AA5: =$B$3/W5 -> 16.171548
A6: 5 | B6: 446647 | D6: 5 | E6: 728 | F6: 875 | G6: 1049 | H6: 1261 | I6: 1509 | J6: 1823 | L6: trojek full | M6: =MAXA(M5+M4-O5-Tabela6[[#This Row],[Done]],0) -> 0 | N6: 15 | O6: =MAXA(-(M5+M4-O5-Tabela6[[#This Row],[Done]]),0) -> 15 | P6: =M6*$B$4 -> 0 | Q6: =Tabela6[[#This Row],[Missing]]*4000 -> 0 | R6: 11 | T6: 3* | U6: 450 | V6: 1* | W6: =G4+0.186*G5 -> 1008.096 | X6: =$U6*$B$4/$W6 -> 36684.899 | Y6: 9600 | Z6: =W6/U6 -> 2.2402133 | AA6: =$B$4/W6 -> 81.521998
A7: 6 | B7: 1005420 | D7: 6 | E7: 818 | F7: 981 | G7: 1178 | H7: 1415 | I7: 1693 | J7: 2044 | L7: trojek 1 | M7: =MAXA(3*(M5+M4-O5)-Tabela6[[#This Row],[Done]],0) -> 0 | N7: 0 | O7: =MAXA(-3*(M4+M5-O5)+Tabela6[[#This Row],[Done]],0) -> 0 | Q7: =Tabela6[[#This Row],[Missing]]*4000 -> 0 | R7: 6 | T7: 3* | U7: 750 | V7: 2* | W7: =G4+G5+0.489*G6 -> 2282.961 | X7: =$U7*$B$4/$W7 -> 26998.49 | Y7: 9600 | Z7: =W7/U7 -> 3.043948 | AA7: =$B$4/W7 -> 35.997987
D8: 7 | E8: 918 | F8: 1102 | G8: 1321 | H8: 1587 | I8: 1899 | J8: 2294 | L8: dwójek full | M8: =MAXA(M7+M6-O7-Tabela6[[#This Row],[Done]],0) -> 0 | N8: 20 | O8: =MAXA(-(M7+M6-O7-Tabela6[[#This Row],[Done]]),0) -> 20 | P8: =M8*$B$3 -> 0 | Q8: =Tabela6[[#This Row],[Missing]]*4000 -> 0 | R8: 9 | T8: 4* | U8: 600 | V8: 1* | W8: =W4 -> 1007.379 | X8: =$U8*$B$5/$W8 -> 113016.05 | Y8: 22300 | Z8: =W8/U8 -> 1.678965 | AA8: =$B$5/W8 -> 188.36009
D9: 8 | E9: 1029 | F9: 1235 | G9: 1483 | H9: 1781 | I9: 2131 | J9: 2574 | L9: dwójek 1 | M9: =MAXA(2*(M7+M6-O7)-Tabela6[[#This Row],[Done]],0) -> 0 | N9: 3 | O9: =MAXA(-(2*M7+M8-Tabela6[[#This Row],[Done]]),0) -> 3 | Q9: =Tabela6[[#This Row],[Missing]]*11000 -> 0 | R9: 20
D10: 9 | E10: 1155 | F10: 1386 | G10: 1663 | H10: 1998 | I10: 2392 | J10: 2888 | L10: jedynek full | M10: 0 | N10: 0 | P10: =Tabela6[[#This Row],[Missing]]*$B$2 -> 0 | Q10: =Tabela6[[#This Row],[Missing]]*4000 -> 0 | R10: 0
D11: 10 | E11: 1296 | F11: 1555 | G11: 1866 | H11: 2243 | I11: 2682 | J11: 3240 | L11: jedynek 1 | M11: =MAXA(2*M10-Tabela6[[#This Row],[Done]],0) -> 0 | N11: 0 | Q11: =Tabela6[[#This Row],[Missing]]*4000 -> 0 | R11: 0
D12: 11 | E12: 1455 | F12: 1745 | G12: 2094 | H12: 2515 | I12: 3010 | J12: 3635 | N12: Total XP to gain | P12: =SUM(Tabela6[XP to gain]) -> 0 | Q12: =SUM(Q3:Q9) -> 22300
D13: 12 | E13: 1631 | F13: 1958 | G13: 2350 | H13: 2823 | I13: 3378 | J13: 4079
D14: 13 | E14: 1831 | F14: 2197 | G14: 2636 | H14: 3167 | I14: 3789 | J14: 4576 | L14: Kolumna1 | M14: Missing | N14: Done | O14: XP to gain | P14: Kolumna2
D15: 14 | E15: 2054 | F15: 2465 | G15: 2957 | H15: 3553 | I15: 4252 | J15: 5135 | L15: piątki 1 | M15: 1 | N15: 0 | O15: 0
D16: 15 | F16: 2765 | G16: 3319 | H16: 3987 | I16: 4770 | J16: 5762 | L16: czworki full | M16: =M15-Tabela66[[#This Row],[Done]] -> 1 | N16: 0 | O16: =M16*$B$5 -> 189750
D17: 16 | F17: 3103 | G17: 3723 | H17: 4473 | I17: 5352 | J17: 6464 | L17: czworek 1 | M17: =MAXA(4-Tabela66[[#This Row],[Done]],0) -> 4 | N17: 0 | P17: 1
D18: 17 | F18: 3481 | G18: 4178 | H18: 5019 | I18: 6006 | J18: 7252 | L18: trojek full | M18: =MAXA(M17-Tabela66[[#This Row],[Done]],0) -> 4 | N18: 0 | O18: =M18*$B$4 -> 328728
D19: 18 | F19: 3906 | G19: 4687 | H19: 5631 | I19: 6738 | J19: 8138 | L19: trojek 1 | M19: =3*(M17+M16)-Tabela66[[#This Row],[Done]] -> 15 | N19: 0 | P19: 1
D20: 19 | F20: 4423 | G20: 5307 | H20: 6376 | I20: 7628 | J20: 9214 | L20: dwójek full | M20: =MAXA(M19+M18-Tabela66[[#This Row],[Done]],0) -> 19 | N20: 0 | O20: =M20*$B$3 -> 680618
D21: 20 | G21: 6009 | H21: 7219 | I21: 8638 | J21: 10431 | L21: dwójek 1 | M21: =2*(M19+M18)-Tabela66[[#This Row],[Done]] -> 38 | N21: 0 | P21: 2
D22: 21 | G22: 6802 | H22: 8172 | I22: 9779 | J22: 11811 | L22: jedynek full | M22: 0 | N22: 0 | O22: =Tabela66[[#This Row],[Missing]]*$B$2 -> 0
D23: 22 | G23: 7703 | H23: 9254 | I23: 11072 | J23: 13371 | L23: jedynek 1 | M23: 0 | N23: 0 | P23: 45
D24: 23 | G24: 8720 | H24: 10476 | I24: 12535 | J24: 15140 | N24: Total XP to gain | O24: =SUM(Tabela66[XP to gain]) -> 1199096
D25: 24 | G25: 9962 | H25: 11969 | I25: 14321 | J25: 17296
D26: 25 | H26: 13673 | I26: 16360 | J26: 19758 | L26: Veromos
D27: 26 | H27: 15619 | I27: 18690 | J27: 22572 | L27: Kolumna1 | M27: Missing | N27: Done | O27: XP to gain
D28: 27 | H28: 17844 | I28: 21350 | J28: 25786 | L28: piątki full | M28: =4-Tabela610[[#This Row],[Done]] -> 1 | N28: 3 | O28: =Tabela610[[#This Row],[Missing]]*$B$6 -> 446647 | P28: 2
D29: 28 | H29: 20386 | I29: 24392 | J29: 29458 | L29: czworki full | M29: =16-Tabela610[[#This Row],[Done]] -> 0 | N29: 16 | O29: =M29*$B$5 -> 0 | P29: 14
D30: 29 | H30: 23495 | I30: 28113 | J30: 33954 | L30: czworek 1 | M30: 0 | N30: 0
D31: 30 | I31: 32404 | J31: 39134 | L31: trojek full | M31: =MAXA(M30-Tabela610[[#This Row],[Done]],0) -> 0 | N31: =O6 -> 15 | O31: =M31*$B$4 -> 0 | P31: 15
D32: 31 | I32: 37348 | J32: 45107 | L32: trojek 1 | M32: =MAXA(3*M30-Tabela610[[#This Row],[Done]],0) -> 0 | N32: =O7 -> 0 | P32: 4
D33: 32 | I33: 43048 | J33: 51990 | L33: dwójek full | M33: 0 | N33: =O8 -> 20 | O33: =M33*$B$3 -> 0 | P33: 5
D34: 33 | I34: 49617 | J34: 59924 | L34: dwójek 1 | M34: =MAXA(2*(M31+M32-10)-Tabela610[[#This Row],[Done]],0) -> 0 | N34: =O9 -> 3 | P34: 34
D35: 34 | I35: 57188 | J35: 69068 | L35: jedynek full | M35: 0 | N35: 0 | O35: =Tabela610[[#This Row],[Missing]]*$B$2 -> 0
D36: 35 | J36: 76085 | L36: jedynek 1 | M36: =MAXA(2*M35-Tabela610[[#This Row],[Done]],0) -> 0 | N36: 500
D37: 36 | J37: 83816 | N37: Total XP to gain | O37: =SUM(Tabela610[XP to gain]) -> 446647
D38: 37 | J38: 92332
D39: 38 | J39: 101712
D40: 39 | J40: 112046
...

Sheet Arkusz3
A1: Rune Set | B1: Skill | C1: Att % | D1: Spd + | E1: nuke % dmg 1st skill | F1: DPS % 1ST skill | G1: Nuke 2 turns | H1: DPS 2 turns | I1: Speed buff | K1: Basic spd | L1: Speed staat + | M1: Att % basic | N1: Att % rune | O1: SPD
A2: Fatal/Att | B2: 1 | C2: =$M$2+N2+0.35 -> 1.65 | D2: =$K$2+$L$2 -> 131 | E2: =(265+1.25*$D2)/100*(1+$C2) -> 11.361875 | F2: =E2 -> 11.361875 | G2: =E2+E6 -> 19.776875 | H2: =F2+F6 -> 19.776875 | I2: =(265+1.25*$D2*1.33)/100*(1+$C2) -> 12.793869 | K2: 100 | L2: 31 | M2: 0.93 | N2: 0.37 | O2: 39
A3: Fatal/Spd | B3: 1 | C3: =C2-N2 -> 1.28 | D3: =D2+$O$2 -> 170 | E3: =(265+1.25*$D3)/100*(1+$C3) -> 10.887 | F3: =E3*D3/$D$2 -> 14.128168 | G3: =E3+E7 -> 17.415 | H3: =F3+F7 -> 22.599618 | I3: =(265+1.25*$D3*1.33)/100*(1+$C3) -> 12.48585 | K3: 100 | L3: 31 | M3: 0.93 | N3: 0.63 | O3: 39
A4: Spd/Att | B4: 1 | C4: =$M$2+N2 -> 1.3 | D4: =D2+20 -> 151 | E4: =(265+1.25*$D4)/100*(1+$C4) -> 10.43625 | F4: =E4*D4/$D$2 -> 12.029571 | G4: =E4+E8 -> 17.06625 | H4: =F4+F8 -> 19.671784 | I4: =(265+1.25*$D4*1.33)/100*(1+$C4) -> 11.868862
A5: Spd/Spd | B5: 1 | C5: =$M$2 -> 0.93 | D5: =D4+$O$2 -> 190 | E5: =(265+1.25*$D5)/100*(1+$C5) -> 9.69825 | F5: =E5*D5/$D$2 -> 14.066164 | G5: =E5+E9 -> 14.44125 | H5: =F5+F9 -> 20.945324 | I5: =(265+1.25*$D5*1.33)/100*(1+$C5) -> 11.210888
A6: Fatal/Att | B6: 2 | C6: =C2 -> 1.65 | D6: =D2 -> 131 | E6: =1.7*3*C6 -> 8.415 | F6: =E6*D6/$D$2 -> 8.415
A7: Fatal/Spd | B7: 2 | C7: =C3 -> 1.28 | D7: =D3 -> 170 | E7: =1.7*3*C7 -> 6.528 | F7: =E7*D7/$D$2 -> 8.4714504
A8: Spd/Att | B8: 2 | C8: =C4 -> 1.3 | D8: =D4 -> 151 | E8: =1.7*3*C8 -> 6.63 | F8: =E8*D8/$D$2 -> 7.6422137
A9: Spd/Spd | B9: 2 | C9: =C5 -> 0.93 | D9: =D5 -> 190 | E9: =1.7*3*C9 -> 4.743 | F9: =E9*D9/$D$2 -> 6.8791603

Sheet Drop analityka
A1: Location | B1: LVL | C1: Stage | D1: Mana drop | E1: Energy Drop | F1: Drop | G1: Quality/Quantity | H1: Grade | I1: Sell Drop | J1: Drop Worth | K1: Fod Worth | L1: Exp Gain | M1: Fail | O1: Drop | P1: Grade | Q1: Drop Worth | R1: Fod Worth | S1: Exp Gain | T1: Exp Gain only 2*+
A2: Tamor Desert | B2: Normal | C2: 1 | D2: 1315 | E2: 2 | I2: 912 | J2: =DropAnalityka[[#This Row],[Sell Drop]]+IFERROR(SUMIFS(Tabela10[Drop Worth],Tabela10[Drop],DropAnalityka[[#This Row],[Drop]],Tabela10[Grade],DropAnalityka[[#This Row],[Grade]])*DropAnalityka[[#This Row],[Quality/Quantity]],0) -> 912 | K2: =IFERROR(SUMIFS(Tabela10[Fod Worth],Tabela10[Drop],DropAnalityka[[#This Row],[Drop]],Tabela10[Grade],DropAnalityka[[#This Row],[Grade]])*DropAnalityka[[#This Row],[Quality/Quantity]],0) -> 0 | L2: =IFERROR(SUMIFS(Tabela10[Exp Gain only 2*+],Tabela10[Drop],DropAnalityka[[#This Row],[Drop]],Tabela10[Grade],DropAnalityka[[#This Row],[Grade]])*DropAnalityka[[#This Row],[Quality/Quantity]],0) -> 0 | O2: Fod | P2: 2* | R2: 11500 | S2: 15120 | T2: 0
A3: Tamor Desert | B3: Normal | C3: 3 | D3: 1255 | E3: 0 | I3: 325 | J3: =DropAnalityka[[#This Row],[Sell Drop]]+IFERROR(SUMIFS(Tabela10[Drop Worth],Tabela10[Drop],DropAnalityka[[#This Row],[Drop]],Tabela10[Grade],DropAnalityka[[#This Row],[Grade]])*DropAnalityka[[#This Row],[Quality/Quantity]],0) -> 325 | K3: =IFERROR(SUMIFS(Tabela10[Fod Worth],Tabela10[Drop],DropAnalityka[[#This Row],[Drop]],Tabela10[Grade],DropAnalityka[[#This Row],[Grade]])*DropAnalityka[[#This Row],[Quality/Quantity]],0) -> 0 | L3: =IFERROR(SUMIFS(Tabela10[Exp Gain only 2*+],Tabela10[Drop],DropAnalityka[[#This Row],[Drop]],Tabela10[Grade],DropAnalityka[[#This Row],[Grade]])*DropAnalityka[[#This Row],[Quality/Quantity]],0) -> 0 | O3: Fod | P3: 3* | R3: 34500 | S3: =3*'EXP lvls'!B2+Tabela4[[#This Row],[EXP to TOP lvl]] -> 81182 | T3: 35822
A4: Tamor Desert | B4: Normal | C4: 3 | D4: 1668 | E4: 1 | F4: Fod | G4: 1 | H4: 2* | I4: 0 | J4: =DropAnalityka[[#This Row],[Sell Drop]]+IFERROR(SUMIFS(Tabela10[Drop Worth],Tabela10[Drop],DropAnalityka[[#This Row],[Drop]],Tabela10[Grade],DropAnalityka[[#This Row],[Grade]])*DropAnalityka[[#This Row],[Quality/Quantity]],0) -> 0 | K4: =IFERROR(SUMIFS(Tabela10[Fod Worth],Tabela10[Drop],DropAnalityka[[#This Row],[Drop]],Tabela10[Grade],DropAnalityka[[#This Row],[Grade]])*DropAnalityka[[#This Row],[Quality/Quantity]],0) -> 11500 | L4: =IFERROR(SUMIFS(Tabela10[Exp Gain only 2*+],Tabela10[Drop],DropAnalityka[[#This Row],[Drop]],Tabela10[Grade],DropAnalityka[[#This Row],[Grade]])*DropAnalityka[[#This Row],[Quality/Quantity]],0) -> 0 | O4: Rainb | P4: 2* | R4: 11500 | S4: =S3 -> 81182 | T4: 35822
A5: Tamor Desert | B5: Normal | C5: 3 | D5: 1008 | E5: 0 | I5: 325 | J5: =DropAnalityka[[#This Row],[Sell Drop]]+IFERROR(SUMIFS(Tabela10[Drop Worth],Tabela10[Drop],DropAnalityka[[#This Row],[Drop]],Tabela10[Grade],DropAnalityka[[#This Row],[Grade]])*DropAnalityka[[#This Row],[Quality/Quantity]],0) -> 325 | K5: =IFERROR(SUMIFS(Tabela10[Fod Worth],Tabela10[Drop],DropAnalityka[[#This Row],[Drop]],Tabela10[Grade],DropAnalityka[[#This Row],[Grade]])*DropAnalityka[[#This Row],[Quality/Quantity]],0) -> 0 | L5: =IFERROR(SUMIFS(Tabela10[Exp Gain only 2*+],Tabela10[Drop],DropAnalityka[[#This Row],[Drop]],Tabela10[Grade],DropAnalityka[[#This Row],[Grade]])*DropAnalityka[[#This Row],[Quality/Quantity]],0) -> 0 | O5: Rainb | P5: 3* | R5: 34500 | S5: =S4+'EXP lvls'!B4 -> 163364 | T5: ='EXP lvls'!B3+'EXP lvls'!B4 -> 118004
A6: Tamor Desert | B6: Normal | C6: 3 | D6: 1619 | E6: 1 | I6: 325 | J6: =DropAnalityka[[#This Row],[Sell Drop]]+IFERROR(SUMIFS(Tabela10[Drop Worth],Tabela10[Drop],DropAnalityka[[#This Row],[Drop]],Tabela10[Grade],DropAnalityka[[#This Row],[Grade]])*DropAnalityka[[#This Row],[Quality/Quantity]],0) -> 325 | K6: =IFERROR(SUMIFS(Tabela10[Fod Worth],Tabela10[Drop],DropAnalityka[[#This Row],[Drop]],Tabela10[Grade],DropAnalityka[[#This Row],[Grade]])*DropAnalityka[[#This Row],[Quality/Quantity]],0) -> 0 | L6: =IFERROR(SUMIFS(Tabela10[Exp Gain only 2*+],Tabela10[Drop],DropAnalityka[[#This Row],[Drop]],Tabela10[Grade],DropAnalityka[[#This Row],[Grade]])*DropAnalityka[[#This Row],[Quality/Quantity]],0) -> 0 | O6: Scroll | P6: 1* | Q6: =(11500-300*5)/5 -> 2000 | S6: 800 | T6: 800
A7: Tamor Desert | B7: Normal | C7: 3 | D7: 1152 | E7: 1 | I7: 720 | J7: =DropAnalityka[[#This Row],[Sell Drop]]+IFERROR(SUMIFS(Tabela10[Drop Worth],Tabela10[Drop],DropAnalityka[[#This Row],[Drop]],Tabela10[Grade],DropAnalityka[[#This Row],[Grade]])*DropAnalityka[[#This Row],[Quality/Quantity]],0) -> 720 | K7: =IFERROR(SUMIFS(Tabela10[Fod Worth],Tabela10[Drop],DropAnalityka[[#This Row],[Drop]],Tabela10[Grade],DropAnalityka[[#This Row],[Grade]])*DropAnalityka[[#This Row],[Quality/Quantity]],0) -> 0 | L7: =IFERROR(SUMIFS(Tabela10[Exp Gain only 2*+],Tabela10[Drop],DropAnalityka[[#This Row],[Drop]],Tabela10[Grade],DropAnalityka[[#This Row],[Grade]])*DropAnalityka[[#This Row],[Quality/Quantity]],0) -> 0 | O7: MystScroll | P7: 1* | Q7: 120000 | R7: 0 | S7: 0 | T7: 0
A8: Tamor Desert | B8: Normal | C8: 3 | D8: 1007 | E8: 0 | F8: Scroll | G8: 1 | H8: 1* | I8: 0 | J8: =DropAnalityka[[#This Row],[Sell Drop]]+IFERROR(SUMIFS(Tabela10[Drop Worth],Tabela10[Drop],DropAnalityka[[#This Row],[Drop]],Tabela10[Grade],DropAnalityka[[#This Row],[Grade]])*DropAnalityka[[#This Row],[Quality/Quantity]],0) -> 2000 | K8: =IFERROR(SUMIFS(Tabela10[Fod Worth],Tabela10[Drop],DropAnalityka[[#This Row],[Drop]],Tabela10[Grade],DropAnalityka[[#This Row],[Grade]])*DropAnalityka[[#This Row],[Quality/Quantity]],0) -> 0 | L8: =IFERROR(SUMIFS(Tabela10[Exp Gain only 2*+],Tabela10[Drop],DropAnalityka[[#This Row],[Drop]],Tabela10[Grade],DropAnalityka[[#This Row],[Grade]])*DropAnalityka[[#This Row],[Quality/Quantity]],0) -> 800 | O8: SumStone | P8: 3* | R8: =R3/40 -> 862.5 | T8: =T3/40 -> 895.55
A9: Tamor Desert | B9: Normal | C9: 3 | D9: 1401 | E9: 0 | F9: Fod | G9: 1 | H9: 2* | I9: 0 | J9: =DropAnalityka[[#This Row],[Sell Drop]]+IFERROR(SUMIFS(Tabela10[Drop Worth],Tabela10[Drop],DropAnalityka[[#This Row],[Drop]],Tabela10[Grade],DropAnalityka[[#This Row],[Grade]])*DropAnalityka[[#This Row],[Quality/Quantity]],0) -> 0 | K9: =IFERROR(SUMIFS(Tabela10[Fod Worth],Tabela10[Drop],DropAnalityka[[#This Row],[Drop]],Tabela10[Grade],DropAnalityka[[#This Row],[Grade]])*DropAnalityka[[#This Row],[Quality/Quantity]],0) -> 11500 | L9: =IFERROR(SUMIFS(Tabela10[Exp Gain only 2*+],Tabela10[Drop],DropAnalityka[[#This Row],[Drop]],Tabela10[Grade],DropAnalityka[[#This Row],[Grade]])*DropAnalityka[[#This Row],[Quality/Quantity]],0) -> 0
A10: Tamor Desert | B10: Normal | C10: 3 | D10: 1705 | E10: 1 | F10: Scroll | G10: 1 | H10: 1* | I10: 0 | J10: =DropAnalityka[[#This Row],[Sell Drop]]+IFERROR(SUMIFS(Tabela10[Drop Worth],Tabela10[Drop],DropAnalityka[[#This Row],[Drop]],Tabela10[Grade],DropAnalityka[[#This Row],[Grade]])*DropAnalityka[[#This Row],[Quality/Quantity]],0) -> 2000 | K10: =IFERROR(SUMIFS(Tabela10[Fod Worth],Tabela10[Drop],DropAnalityka[[#This Row],[Drop]],Tabela10[Grade],DropAnalityka[[#This Row],[Grade]])*DropAnalityka[[#This Row],[Quality/Quantity]],0) -> 0 | L10: =IFERROR(SUMIFS(Tabela10[Exp Gain only 2*+],Tabela10[Drop],DropAnalityka[[#This Row],[Drop]],Tabela10[Grade],DropAnalityka[[#This Row],[Grade]])*DropAnalityka[[#This Row],[Quality/Quantity]],0) -> 800 | O10: Licznik z LVL | P10: Etykiety kolumn
A11: Tamor Desert | B11: Normal | C11: 3 | D11: 1033 | E11: 0 | I11: 720 | J11: =DropAnalityka[[#This Row],[Sell Drop]]+IFERROR(SUMIFS(Tabela10[Drop Worth],Tabela10[Drop],DropAnalityka[[#This Row],[Drop]],Tabela10[Grade],DropAnalityka[[#This Row],[Grade]])*DropAnalityka[[#This Row],[Quality/Quantity]],0) -> 720 | K11: =IFERROR(SUMIFS(Tabela10[Fod Worth],Tabela10[Drop],DropAnalityka[[#This Row],[Drop]],Tabela10[Grade],DropAnalityka[[#This Row],[Grade]])*DropAnalityka[[#This Row],[Quality/Quantity]],0) -> 0 | L11: =IFERROR(SUMIFS(Tabela10[Exp Gain only 2*+],Tabela10[Drop],DropAnalityka[[#This Row],[Drop]],Tabela10[Grade],DropAnalityka[[#This Row],[Grade]])*DropAnalityka[[#This Row],[Quality/Quantity]],0) -> 0 | O11: Etykiety wierszy | P11: 0 | Q11: 1* | R11: 2* | S11: 3* | T11: 4* | U11: 5* | V11: 6* | W11: (puste) | X11: Suma końcowa
A12: Tamor Desert | B12: Normal | C12: 3 | D12: 645 | E12: 0 | F12: Fod | G12: 1 | H12: 2* | I12: 0 | J12: =DropAnalityka[[#This Row],[Sell Drop]]+IFERROR(SUMIFS(Tabela10[Drop Worth],Tabela10[Drop],DropAnalityka[[#This Row],[Drop]],Tabela10[Grade],DropAnalityka[[#This Row],[Grade]])*DropAnalityka[[#This Row],[Quality/Quantity]],0) -> 0 | K12: =IFERROR(SUMIFS(Tabela10[Fod Worth],Tabela10[Drop],DropAnalityka[[#This Row],[Drop]],Tabela10[Grade],DropAnalityka[[#This Row],[Grade]])*DropAnalityka[[#This Row],[Quality/Quantity]],0) -> 11500 | L12: =IFERROR(SUMIFS(Tabela10[Exp Gain only 2*+],Tabela10[Drop],DropAnalityka[[#This Row],[Drop]],Tabela10[Grade],DropAnalityka[[#This Row],[Grade]])*DropAnalityka[[#This Row],[Quality/Quantity]],0) -> 0 | O12: Dragon | Q12: 35 | R12: 6 | S12: 3 | T12: 46 | U12: 43 | V12: 10 | W12: 4 | X12: 147
A13: Tamor Desert | B13: Normal | C13: 3 | D13: 1091 | E13: 4 | I13: 325 | J13: =DropAnalityka[[#This Row],[Sell Drop]]+IFERROR(SUMIFS(Tabela10[Drop Worth],Tabela10[Drop],DropAnalityka[[#This Row],[Drop]],Tabela10[Grade],DropAnalityka[[#This Row],[Grade]])*DropAnalityka[[#This Row],[Quality/Quantity]],0) -> 325 | K13: =IFERROR(SUMIFS(Tabela10[Fod Worth],Tabela10[Drop],DropAnalityka[[#This Row],[Drop]],Tabela10[Grade],DropAnalityka[[#This Row],[Grade]])*DropAnalityka[[#This Row],[Quality/Quantity]],0) -> 0 | L13: =IFERROR(SUMIFS(Tabela10[Exp Gain only 2*+],Tabela10[Drop],DropAnalityka[[#This Row],[Drop]],Tabela10[Grade],DropAnalityka[[#This Row],[Grade]])*DropAnalityka[[#This Row],[Quality/Quantity]],0) -> 0 | O13: 7 | T13: 3 | X13: 3
A14: Tamor Desert | B14: Normal | C14: 3 | D14: 519 | E14: 2 | I14: 487 | J14: =DropAnalityka[[#This Row],[Sell Drop]]+IFERROR(SUMIFS(Tabela10[Drop Worth],Tabela10[Drop],DropAnalityka[[#This Row],[Drop]],Tabela10[Grade],DropAnalityka[[#This Row],[Grade]])*DropAnalityka[[#This Row],[Quality/Quantity]],0) -> 487 | K14: =IFERROR(SUMIFS(Tabela10[Fod Worth],Tabela10[Drop],DropAnalityka[[#This Row],[Drop]],Tabela10[Grade],DropAnalityka[[#This Row],[Grade]])*DropAnalityka[[#This Row],[Quality/Quantity]],0) -> 0 | L14: =IFERROR(SUMIFS(Tabela10[Exp Gain only 2*+],Tabela10[Drop],DropAnalityka[[#This Row],[Drop]],Tabela10[Grade],DropAnalityka[[#This Row],[Grade]])*DropAnalityka[[#This Row],[Quality/Quantity]],0) -> 0 | O14: 8 | Q14: 6 | R14: 1 | T14: 6 | U14: 5 | X14: 18
A15: Tamor Desert | B15: Normal | C15: 3 | D15: 1378 | E15: 1 | I15: 325 | J15: =DropAnalityka[[#This Row],[Sell Drop]]+IFERROR(SUMIFS(Tabela10[Drop Worth],Tabela10[Drop],DropAnalityka[[#This Row],[Drop]],Tabela10[Grade],DropAnalityka[[#This Row],[Grade]])*DropAnalityka[[#This Row],[Quality/Quantity]],0) -> 325 | K15: =IFERROR(SUMIFS(Tabela10[Fod Worth],Tabela10[Drop],DropAnalityka[[#This Row],[Drop]],Tabela10[Grade],DropAnalityka[[#This Row],[Grade]])*DropAnalityka[[#This Row],[Quality/Quantity]],0) -> 0 | L15: =IFERROR(SUMIFS(Tabela10[Exp Gain only 2*+],Tabela10[Drop],DropAnalityka[[#This Row],[Drop]],Tabela10[Grade],DropAnalityka[[#This Row],[Grade]])*DropAnalityka[[#This Row],[Quality/Quantity]],0) -> 0 | O15: 9 | Q15: 24 | R15: 4 | S15: 2 | T15: 35 | U15: 32 | V15: 9 | W15: 4 | X15: 110
A16: Tamor Desert | B16: Normal | C16: 3 | D16: 1455 | E16: 1 | I16: 325 | J16: =DropAnalityka[[#This Row],[Sell Drop]]+IFERROR(SUMIFS(Tabela10[Drop Worth],Tabela10[Drop],DropAnalityka[[#This Row],[Drop]],Tabela10[Grade],DropAnalityka[[#This Row],[Grade]])*DropAnalityka[[#This Row],[Quality/Quantity]],0) -> 325 | K16: =IFERROR(SUMIFS(Tabela10[Fod Worth],Tabela10[Drop],DropAnalityka[[#This Row],[Drop]],Tabela10[Grade],DropAnalityka[[#This Row],[Grade]])*DropAnalityka[[#This Row],[Quality/Quantity]],0) -> 0 | L16: =IFERROR(SUMIFS(Tabela10[Exp Gain only 2*+],Tabela10[Drop],DropAnalityka[[#This Row],[Drop]],Tabela10[Grade],DropAnalityka[[#This Row],[Grade]])*DropAnalityka[[#This Row],[Quality/Quantity]],0) -> 0 | O16: 10 | Q16: 5 | R16: 1 | S16: 1 | T16: 2 | U16: 6 | V16: 1 | X16: 16
A17: Tamor Desert | B17: Normal | C17: 3 | D17: 790 | E17: 2 | F17: Fod | G17: 1 | H17: 1* | I17: 0 | J17: =DropAnalityka[[#This Row],[Sell Drop]]+IFERROR(SUMIFS(Tabela10[Drop Worth],Tabela10[Drop],DropAnalityka[[#This Row],[Drop]],Tabela10[Grade],DropAnalityka[[#This Row],[Grade]])*DropAnalityka[[#This Row],[Quality/Quantity]],0) -> 0 | K17: =IFERROR(SUMIFS(Tabela10[Fod Worth],Tabela10[Drop],DropAnalityka[[#This Row],[Drop]],Tabela10[Grade],DropAnalityka[[#This Row],[Grade]])*DropAnalityka[[#This Row],[Quality/Quantity]],0) -> 0 | L17: =IFERROR(SUMIFS(Tabela10[Exp Gain only 2*+],Tabela10[Drop],DropAnalityka[[#This Row],[Drop]],Tabela10[Grade],DropAnalityka[[#This Row],[Grade]])*DropAnalityka[[#This Row],[Quality/Quantity]],0) -> 0 | O17: Giants | P17: 1 | Q17: 60 | R17: 11 | S17: 7 | T17: 86 | U17: 105 | V17: 12 | W17: 21 | X17: 303
A18: Tamor Desert | B18: Normal | C18: 3 | D18: 1881 | E18: 2 | F18: Scroll | G18: 1 | H18: 1* | I18: 0 | J18: =DropAnalityka[[#This Row],[Sell Drop]]+IFERROR(SUMIFS(Tabela10[Drop Worth],Tabela10[Drop],DropAnalityka[[#This Row],[Drop]],Tabela10[Grade],DropAnalityka[[#This Row],[Grade]])*DropAnalityka[[#This Row],[Quality/Quantity]],0) -> 2000 | K18: =IFERROR(SUMIFS(Tabela10[Fod Worth],Tabela10[Drop],DropAnalityka[[#This Row],[Drop]],Tabela10[Grade],DropAnalityka[[#This Row],[Grade]])*DropAnalityka[[#This Row],[Quality/Quantity]],0) -> 0 | L18: =IFERROR(SUMIFS(Tabela10[Exp Gain only 2*+],Tabela10[Drop],DropAnalityka[[#This Row],[Drop]],Tabela10[Grade],DropAnalityka[[#This Row],[Grade]])*DropAnalityka[[#This Row],[Quality/Quantity]],0) -> 800 | O18: 3 | W18: 1 | X18: 1
A19: Tamor Desert | B19: Normal | C19: 3 | D19: 1508 | E19: 0 | I19: 325 | J19: =DropAnalityka[[#This Row],[Sell Drop]]+IFERROR(SUMIFS(Tabela10[Drop Worth],Tabela10[Drop],DropAnalityka[[#This Row],[Drop]],Tabela10[Grade],DropAnalityka[[#This Row],[Grade]])*DropAnalityka[[#This Row],[Quality/Quantity]],0) -> 325 | K19: =IFERROR(SUMIFS(Tabela10[Fod Worth],Tabela10[Drop],DropAnalityka[[#This Row],[Drop]],Tabela10[Grade],DropAnalityka[[#This Row],[Grade]])*DropAnalityka[[#This Row],[Quality/Quantity]],0) -> 0 | L19: =IFERROR(SUMIFS(Tabela10[Exp Gain only 2*+],Tabela10[Drop],DropAnalityka[[#This Row],[Drop]],Tabela10[Grade],DropAnalityka[[#This Row],[Grade]])*DropAnalityka[[#This Row],[Quality/Quantity]],0) -> 0 | O19: 4 | W19: 1 | X19: 1
A20: Tamor Desert | B20: Normal | C20: 3 | D20: 970 | E20: 0 | I20: 433 | J20: =DropAnalityka[[#This Row],[Sell Drop]]+IFERROR(SUMIFS(Tabela10[Drop Worth],Tabela10[Drop],DropAnalityka[[#This Row],[Drop]],Tabela10[Grade],DropAnalityka[[#This Row],[Grade]])*DropAnalityka[[#This Row],[Quality/Quantity]],0) -> 433 | K20: =IFERROR(SUMIFS(Tabela10[Fod Worth],Tabela10[Drop],DropAnalityka[[#This Row],[Drop]],Tabela10[Grade],DropAnalityka[[#This Row],[Grade]])*DropAnalityka[[#This Row],[Quality/Quantity]],0) -> 0 | L20: =IFERROR(SUMIFS(Tabela10[Exp Gain only 2*+],Tabela10[Drop],DropAnalityka[[#This Row],[Drop]],Tabela10[Grade],DropAnalityka[[#This Row],[Grade]])*DropAnalityka[[#This Row],[Quality/Quantity]],0) -> 0 | O20: 5 | Q20: 5 | W20: 11 | X20: 16
A21: Tamor Desert | B21: Normal | C21: 3 | D21: 1863 | E21: 0 | I21: 379 | J21: =DropAnalityka[[#This Row],[Sell Drop]]+IFERROR(SUMIFS(Tabela10[Drop Worth],Tabela10[Drop],DropAnalityka[[#This Row],[Drop]],Tabela10[Grade],DropAnalityka[[#This Row],[Grade]])*DropAnalityka[[#This Row],[Quality/Quantity]],0) -> 379 | K21: =IFERROR(SUMIFS(Tabela10[Fod Worth],Tabela10[Drop],DropAnalityka[[#This Row],[Drop]],Tabela10[Grade],DropAnalityka[[#This Row],[Grade]])*DropAnalityka[[#This Row],[Quality/Quantity]],0) -> 0 | L21: =IFERROR(SUMIFS(Tabela10[Exp Gain only 2*+],Tabela10[Drop],DropAnalityka[[#This Row],[Drop]],Tabela10[Grade],DropAnalityka[[#This Row],[Grade]])*DropAnalityka[[#This Row],[Quality/Quantity]],0) -> 0 | O21: 6 | Q21: 3 | R21: 1 | T21: 1 | W21: 6 | X21: 11
A22: Tamor Desert | B22: Normal | C22: 3 | D22: 1298 | E22: 1 | F22: Fod | G22: 1 | H22: 1* | I22: 0 | J22: =DropAnalityka[[#This Row],[Sell Drop]]+IFERROR(SUMIFS(Tabela10[Drop Worth],Tabela10[Drop],DropAnalityka[[#This Row],[Drop]],Tabela10[Grade],DropAnalityka[[#This Row],[Grade]])*DropAnalityka[[#This Row],[Quality/Quantity]],0) -> 0 | K22: =IFERROR(SUMIFS(Tabela10[Fod Worth],Tabela10[Drop],DropAnalityka[[#This Row],[Drop]],Tabela10[Grade],DropAnalityka[[#This Row],[Grade]])*DropAnalityka[[#This Row],[Quality/Quantity]],0) -> 0 | L22: =IFERROR(SUMIFS(Tabela10[Exp Gain only 2*+],Tabela10[Drop],DropAnalityka[[#This Row],[Drop]],Tabela10[Grade],DropAnalityka[[#This Row],[Grade]])*DropAnalityka[[#This Row],[Quality/Quantity]],0) -> 0 | O22: 7 | Q22: 17 | R22: 1 | S22: 3 | T22: 23 | U22: 5 | W22: 1 | X22: 50
A23: Tamor Desert | B23: Normal | C23: 3 | D23: 867 | E23: 2 | I23: 325 | J23: =DropAnalityka[[#This Row],[Sell Drop]]+IFERROR(SUMIFS(Tabela10[Drop Worth],Tabela10[Drop],DropAnalityka[[#This Row],[Drop]],Tabela10[Grade],DropAnalityka[[#This Row],[Grade]])*DropAnalityka[[#This Row],[Quality/Quantity]],0) -> 325 | K23: =IFERROR(SUMIFS(Tabela10[Fod Worth],Tabela10[Drop],DropAnalityka[[#This Row],[Drop]],Tabela10[Grade],DropAnalityka[[#This Row],[Grade]])*DropAnalityka[[#This Row],[Quality/Quantity]],0) -> 0 | L23: =IFERROR(SUMIFS(Tabela10[Exp Gain only 2*+],Tabela10[Drop],DropAnalityka[[#This Row],[Drop]],Tabela10[Grade],DropAnalityka[[#This Row],[Grade]])*DropAnalityka[[#This Row],[Quality/Quantity]],0) -> 0 | O23: 8 | Q23: 8 | T23: 17 | U23: 11 | W23: 1 | X23: 37
A24: Tamor Desert | B24: Normal | C24: 3 | D24: 1453 | E24: 1 | I24: 325 | J24: =DropAnalityka[[#This Row],[Sell Drop]]+IFERROR(SUMIFS(Tabela10[Drop Worth],Tabela10[Drop],DropAnalityka[[#This Row],[Drop]],Tabela10[Grade],DropAnalityka[[#This Row],[Grade]])*DropAnalityka[[#This Row],[Quality/Quantity]],0) -> 325 | K24: =IFERROR(SUMIFS(Tabela10[Fod Worth],Tabela10[Drop],DropAnalityka[[#This Row],[Drop]],Tabela10[Grade],DropAnalityka[[#This Row],[Grade]])*DropAnalityka[[#This Row],[Quality/Quantity]],0) -> 0 | L24: =IFERROR(SUMIFS(Tabela10[Exp Gain only 2*+],Tabela10[Drop],DropAnalityka[[#This Row],[Drop]],Tabela10[Grade],DropAnalityka[[#This Row],[Grade]])*DropAnalityka[[#This Row],[Quality/Quantity]],0) -> 0 | O24: 10 | P24: 1 | Q24: 27 | R24: 9 | S24: 4 | T24: 45 | U24: 89 | V24: 12 | X24: 187
A25: Tamor Desert | B25: Normal | C25: 3 | D25: 1293 | E25: 0 | F25: Scroll | G25: 1 | H25: 1* | I25: 0 | J25: =DropAnalityka[[#This Row],[Sell Drop]]+IFERROR(SUMIFS(Tabela10[Drop Worth],Tabela10[Drop],DropAnalityka[[#This Row],[Drop]],Tabela10[Grade],DropAnalityka[[#This Row],[Grade]])*DropAnalityka[[#This Row],[Quality/Quantity]],0) -> 2000 | K25: =IFERROR(SUMIFS(Tabela10[Fod Worth],Tabela10[Drop],DropAnalityka[[#This Row],[Drop]],Tabela10[Grade],DropAnalityka[[#This Row],[Grade]])*DropAnalityka[[#This Row],[Quality/Quantity]],0) -> 0 | L25: =IFERROR(SUMIFS(Tabela10[Exp Gain only 2*+],Tabela10[Drop],DropAnalityka[[#This Row],[Drop]],Tabela10[Grade],DropAnalityka[[#This Row],[Grade]])*DropAnalityka[[#This Row],[Quality/Quantity]],0) -> 800 | O25: Suma końcowa | P25: 1 | Q25: 95 | R25: 17 | S25: 10 | T25: 132 | U25: 148 | V25: 22 | W25: 25 | X25: 450
A26: Tamor Desert | B26: Normal | C26: 3 | D26: 1406 | E26: 0 | I26: 325 | J26: =DropAnalityka[[#This Row],[Sell Drop]]+IFERROR(SUMIFS(Tabela10[Drop Worth],Tabela10[Drop],DropAnalityka[[#This Row],[Drop]],Tabela10[Grade],DropAnalityka[[#This Row],[Grade]])*DropAnalityka[[#This Row],[Quality/Quantity]],0) -> 325 | K26: =IFERROR(SUMIFS(Tabela10[Fod Worth],Tabela10[Drop],DropAnalityka[[#This Row],[Drop]],Tabela10[Grade],DropAnalityka[[#This Row],[Grade]])*DropAnalityka[[#This Row],[Quality/Quantity]],0) -> 0 | L26: =IFERROR(SUMIFS(Tabela10[Exp Gain only 2*+],Tabela10[Drop],DropAnalityka[[#This Row],[Drop]],Tabela10[Grade],DropAnalityka[[#This Row],[Grade]])*DropAnalityka[[#This Row],[Quality/Quantity]],0) -> 0
A27: Tamor Desert | B27: Normal | C27: 3 | D27: 1172 | E27: 1 | F27: Scroll | G27: 1 | H27: 1* | I27: 0 | J27: =DropAnalityka[[#This Row],[Sell Drop]]+IFERROR(SUMIFS(Tabela10[Drop Worth],Tabela10[Drop],DropAnalityka[[#This Row],[Drop]],Tabela10[Grade],DropAnalityka[[#This Row],[Grade]])*DropAnalityka[[#This Row],[Quality/Quantity]],0) -> 2000 | K27: =IFERROR(SUMIFS(Tabela10[Fod Worth],Tabela10[Drop],DropAnalityka[[#This Row],[Drop]],Tabela10[Grade],DropAnalityka[[#This Row],[Grade]])*DropAnalityka[[#This Row],[Quality/Quantity]],0) -> 0 | L27: =IFERROR(SUMIFS(Tabela10[Exp Gain only 2*+],Tabela10[Drop],DropAnalityka[[#This Row],[Drop]],Tabela10[Grade],DropAnalityka[[#This Row],[Grade]])*DropAnalityka[[#This Row],[Quality/Quantity]],0) -> 800
A28: Tamor Desert | B28: Normal | C28: 3 | D28: 1517 | E28: 2 | I28: 325 | J28: =DropAnalityka[[#This Row],[Sell Drop]]+IFERROR(SUMIFS(Tabela10[Drop Worth],Tabela10[Drop],DropAnalityka[[#This Row],[Drop]],Tabela10[Grade],DropAnalityka[[#This Row],[Grade]])*DropAnalityka[[#This Row],[Quality/Quantity]],0) -> 325 | K28: =IFERROR(SUMIFS(Tabela10[Fod Worth],Tabela10[Drop],DropAnalityka[[#This Row],[Drop]],Tabela10[Grade],DropAnalityka[[#This Row],[Grade]])*DropAnalityka[[#This Row],[Quality/Quantity]],0) -> 0 | L28: =IFERROR(SUMIFS(Tabela10[Exp Gain only 2*+],Tabela10[Drop],DropAnalityka[[#This Row],[Drop]],Tabela10[Grade],DropAnalityka[[#This Row],[Grade]])*DropAnalityka[[#This Row],[Quality/Quantity]],0) -> 0
A29: Tamor Desert | B29: Normal | C29: 3 | D29: 679 | E29: 0 | I29: 379 | J29: =DropAnalityka[[#This Row],[Sell Drop]]+IFERROR(SUMIFS(Tabela10[Drop Worth],Tabela10[Drop],DropAnalityka[[#This Row],[Drop]],Tabela10[Grade],DropAnalityka[[#This Row],[Grade]])*DropAnalityka[[#This Row],[Quality/Quantity]],0) -> 379 | K29: =IFERROR(SUMIFS(Tabela10[Fod Worth],Tabela10[Drop],DropAnalityka[[#This Row],[Drop]],Tabela10[Grade],DropAnalityka[[#This Row],[Grade]])*DropAnalityka[[#This Row],[Quality/Quantity]],0) -> 0 | L29: =IFERROR(SUMIFS(Tabela10[Exp Gain only 2*+],Tabela10[Drop],DropAnalityka[[#This Row],[Drop]],Tabela10[Grade],DropAnalityka[[#This Row],[Grade]])*DropAnalityka[[#This Row],[Quality/Quantity]],0) -> 0
A30: Tamor Desert | B30: Normal | C30: 3 | D30: 1263 | E30: 0 | I30: 487 | J30: =DropAnalityka[[#This Row],[Sell Drop]]+IFERROR(SUMIFS(Tabela10[Drop Worth],Tabela10[Drop],DropAnalityka[[#This Row],[Drop]],Tabela10[Grade],DropAnalityka[[#This Row],[Grade]])*DropAnalityka[[#This Row],[Quality/Quantity]],0) -> 487 | K30: =IFERROR(SUMIFS(Tabela10[Fod Worth],Tabela10[Drop],DropAnalityka[[#This Row],[Drop]],Tabela10[Grade],DropAnalityka[[#This Row],[Grade]])*DropAnalityka[[#This Row],[Quality/Quantity]],0) -> 0 | L30: =IFERROR(SUMIFS(Tabela10[Exp Gain only 2*+],Tabela10[Drop],DropAnalityka[[#This Row],[Drop]],Tabela10[Grade],DropAnalityka[[#This Row],[Grade]])*DropAnalityka[[#This Row],[Quality/Quantity]],0) -> 0
A31: Tamor Desert | B31: Normal | C31: 3 | D31: 497 | E31: 1 | F31: Scroll | G31: 1 | H31: 1* | I31: 0 | J31: =DropAnalityka[[#This Row],[Sell Drop]]+IFERROR(SUMIFS(Tabela10[Drop Worth],Tabela10[Drop],DropAnalityka[[#This Row],[Drop]],Tabela10[Grade],DropAnalityka[[#This Row],[Grade]])*DropAnalityka[[#This Row],[Quality/Quantity]],0) -> 2000 | K31: =IFERROR(SUMIFS(Tabela10[Fod Worth],Tabela10[Drop],DropAnalityka[[#This Row],[Drop]],Tabela10[Grade],DropAnalityka[[#This Row],[Grade]])*DropAnalityka[[#This Row],[Quality/Quantity]],0) -> 0 | L31: =IFERROR(SUMIFS(Tabela10[Exp Gain only 2*+],Tabela10[Drop],DropAnalityka[[#This Row],[Drop]],Tabela10[Grade],DropAnalityka[[#This Row],[Grade]])*DropAnalityka[[#This Row],[Quality/Quantity]],0) -> 800
A32: Tamor Desert | B32: Normal | C32: 3 | D32: 621 | E32: 1 | I32: 720 | J32: =DropAnalityka[[#This Row],[Sell Drop]]+IFERROR(SUMIFS(Tabela10[Drop Worth],Tabela10[Drop],DropAnalityka[[#This Row],[Drop]],Tabela10[Grade],DropAnalityka[[#This Row],[Grade]])*DropAnalityka[[#This Row],[Quality/Quantity]],0) -> 720 | K32: =IFERROR(SUMIFS(Tabela10[Fod Worth],Tabela10[Drop],DropAnalityka[[#This Row],[Drop]],Tabela10[Grade],DropAnalityka[[#This Row],[Grade]])*DropAnalityka[[#This Row],[Quality/Quantity]],0) -> 0 | L32: =IFERROR(SUMIFS(Tabela10[Exp Gain only 2*+],Tabela10[Drop],DropAnalityka[[#This Row],[Drop]],Tabela10[Grade],DropAnalityka[[#This Row],[Grade]])*DropAnalityka[[#This Row],[Quality/Quantity]],0) -> 0
A33: Tamor Desert | B33: Normal | C33: 3 | D33: 1165 | E33: 1 | I33: 325 | J33: =DropAnalityka[[#This Row],[Sell Drop]]+IFERROR(SUMIFS(Tabela10[Drop Worth],Tabela10[Drop],DropAnalityka[[#This Row],[Drop]],Tabela10[Grade],DropAnalityka[[#This Row],[Grade]])*DropAnalityka[[#This Row],[Quality/Quantity]],0) -> 325 | K33: =IFERROR(SUMIFS(Tabela10[Fod Worth],Tabela10[Drop],DropAnalityka[[#This Row],[Drop]],Tabela10[Grade],DropAnalityka[[#This Row],[Grade]])*DropAnalityka[[#This Row],[Quality/Quantity]],0) -> 0 | L33: =IFERROR(SUMIFS(Tabela10[Exp Gain only 2*+],Tabela10[Drop],DropAnalityka[[#This Row],[Drop]],Tabela10[Grade],DropAnalityka[[#This Row],[Grade]])*DropAnalityka[[#This Row],[Quality/Quantity]],0) -> 0
A34: Tamor Desert | B34: Normal | C34: 3 | D34: 1390 | E34: 1 | F34: Scroll | G34: 1 | H34: 1* | I34: 0 | J34: =DropAnalityka[[#This Row],[Sell Drop]]+IFERROR(SUMIFS(Tabela10[Drop Worth],Tabela10[Drop],DropAnalityka[[#This Row],[Drop]],Tabela10[Grade],DropAnalityka[[#This Row],[Grade]])*DropAnalityka[[#This Row],[Quality/Quantity]],0) -> 2000 | K34: =IFERROR(SUMIFS(Tabela10[Fod Worth],Tabela10[Drop],DropAnalityka[[#This Row],[Drop]],Tabela10[Grade],DropAnalityka[[#This Row],[Grade]])*DropAnalityka[[#This Row],[Quality/Quantity]],0) -> 0 | L34: =IFERROR(SUMIFS(Tabela10[Exp Gain only 2*+],Tabela10[Drop],DropAnalityka[[#This Row],[Drop]],Tabela10[Grade],DropAnalityka[[#This Row],[Grade]])*DropAnalityka[[#This Row],[Quality/Quantity]],0) -> 800
A35: Tamor Desert | B35: Normal | C35: 3 | D35: 999 | E35: 1 | F35: Scroll | G35: 1 | H35: 1* | I35: 0 | J35: =DropAnalityka[[#This Row],[Sell Drop]]+IFERROR(SUMIFS(Tabela10[Drop Worth],Tabela10[Drop],DropAnalityka[[#This Row],[Drop]],Tabela10[Grade],DropAnalityka[[#This Row],[Grade]])*DropAnalityka[[#This Row],[Quality/Quantity]],0) -> 2000 | K35: =IFERROR(SUMIFS(Tabela10[Fod Worth],Tabela10[Drop],DropAnalityka[[#This Row],[Drop]],Tabela10[Grade],DropAnalityka[[#This Row],[Grade]])*DropAnalityka[[#This Row],[Quality/Quantity]],0) -> 0 | L35: =IFERROR(SUMIFS(Tabela10[Exp Gain only 2*+],Tabela10[Drop],DropAnalityka[[#This Row],[Drop]],Tabela10[Grade],DropAnalityka[[#This Row],[Grade]])*DropAnalityka[[#This Row],[Quality/Quantity]],0) -> 800
A36: Tamor Desert | B36: Normal | C36: 3 | D36: 1117 | E36: 2 | I36: 325 | J36: =DropAnalityka[[#This Row],[Sell Drop]]+IFERROR(SUMIFS(Tabela10[Drop Worth],Tabela10[Drop],DropAnalityka[[#This Row],[Drop]],Tabela10[Grade],DropAnalityka[[#This Row],[Grade]])*DropAnalityka[[#This Row],[Quality/Quantity]],0) -> 325 | K36: =IFERROR(SUMIFS(Tabela10[Fod Worth],Tabela10[Drop],DropAnalityka[[#This Row],[Drop]],Tabela10[Grade],DropAnalityka[[#This Row],[Grade]])*DropAnalityka[[#This Row],[Quality/Quantity]],0) -> 0 | L36: =IFERROR(SUMIFS(Tabela10[Exp Gain only 2*+],Tabela10[Drop],DropAnalityka[[#This Row],[Drop]],Tabela10[Grade],DropAnalityka[[#This Row],[Grade]])*DropAnalityka[[#This Row],[Quality/Quantity]],0) -> 0
A37: Tamor Desert | B37: Normal | C37: 3 | D37: 794 | E37: 1 | I37: 325 | J37: =DropAnalityka[[#This Row],[Sell Drop]]+IFERROR(SUMIFS(Tabela10[Drop Worth],Tabela10[Drop],DropAnalityka[[#This Row],[Drop]],Tabela10[Grade],DropAnalityka[[#This Row],[Grade]])*DropAnalityka[[#This Row],[Quality/Quantity]],0) -> 325 | K37: =IFERROR(SUMIFS(Tabela10[Fod Worth],Tabela10[Drop],DropAnalityka[[#This Row],[Drop]],Tabela10[Grade],DropAnalityka[[#This Row],[Grade]])*DropAnalityka[[#This Row],[Quality/Quantity]],0) -> 0 | L37: =IFERROR(SUMIFS(Tabela10[Exp Gain only 2*+],Tabela10[Drop],DropAnalityka[[#This Row],[Drop]],Tabela10[Grade],DropAnalityka[[#This Row],[Grade]])*DropAnalityka[[#This Row],[Quality/Quantity]],0) -> 0
A38: Tamor Desert | B38: Normal | C38: 3 | D38: 1432 | E38: 1 | I38: 325 | J38: =DropAnalityka[[#This Row],[Sell Drop]]+IFERROR(SUMIFS(Tabela10[Drop Worth],Tabela10[Drop],DropAnalityka[[#This Row],[Drop]],Tabela10[Grade],DropAnalityka[[#This Row],[Grade]])*DropAnalityka[[#This Row],[Quality/Quantity]],0) -> 325 | K38: =IFERROR(SUMIFS(Tabela10[Fod Worth],Tabela10[Drop],DropAnalityka[[#This Row],[Drop]],Tabela10[Grade],DropAnalityka[[#This Row],[Grade]])*DropAnalityka[[#This Row],[Quality/Quantity]],0) -> 0 | L38: =IFERROR(SUMIFS(Tabela10[Exp Gain only 2*+],Tabela10[Drop],DropAnalityka[[#This Row],[Drop]],Tabela10[Grade],DropAnalityka[[#This Row],[Grade]])*DropAnalityka[[#This Row],[Quality/Quantity]],0) -> 0
A39: Tamor Desert | B39: Normal | C39: 3 | D39: 1485 | E39: 0 | I39: 433 | J39: =DropAnalityka[[#This Row],[Sell Drop]]+IFERROR(SUMIFS(Tabela10[Drop Worth],Tabela10[Drop],DropAnalityka[[#This Row],[Drop]],Tabela10[Grade],DropAnalityka[[#This Row],[Grade]])*DropAnalityka[[#This Row],[Quality/Quantity]],0) -> 433 | K39: =IFERROR(SUMIFS(Tabela10[Fod Worth],Tabela10[Drop],DropAnalityka[[#This Row],[Drop]],Tabela10[Grade],DropAnalityka[[#This Row],[Grade]])*DropAnalityka[[#This Row],[Quality/Quantity]],0) -> 0 | L39: =IFERROR(SUMIFS(Tabela10[Exp Gain only 2*+],Tabela10[Drop],DropAnalityka[[#This Row],[Drop]],Tabela10[Grade],DropAnalityka[[#This Row],[Grade]])*DropAnalityka[[#This Row],[Quality/Quantity]],0) -> 0
A40: Tamor Desert | B40: Normal | C40: 3 | D40: 1301 | E40: 1 | I40: 379 | J40: =DropAnalityka[[#This Row],[Sell Drop]]+IFERROR(SUMIFS(Tabela10[Drop Worth],Tabela10[Drop],DropAnalityka[[#This Row],[Drop]],Tabela10[Grade],DropAnalityka[[#This Row],[Grade]])*DropAnalityka[[#This Row],[Quality/Quantity]],0) -> 379 | K40: =IFERROR(SUMIFS(Tabela10[Fod Worth],Tabela10[Drop],DropAnalityka[[#This Row],[Drop]],Tabela10[Grade],DropAnalityka[[#This Row],[Grade]])*DropAnalityka[[#This Row],[Quality/Quantity]],0) -> 0 | L40: =IFERROR(SUMIFS(Tabela10[Exp Gain only 2*+],Tabela10[Drop],DropAnalityka[[#This Row],[Drop]],Tabela10[Grade],DropAnalityka[[#This Row],[Grade]])*DropAnalityka[[#This Row],[Quality/Quantity]],0) -> 0
...

Sheet Fusion
F5: Water | I5: Wind | L5: Fire | O5: Magic | R5: Dark
C6: GOT | D6: Grade/lvl | F6: Low | G6: Mid | H6: High | I6: Low | J6: Mid | K6: High | L6: Low | M6: Mid | N6: High | O6: Low | P6: Mid | Q6: High | R6: Low | S6: Mid | T6: High
A7: VEROMOS | B7: Undine(water) | D7: 5* 35
A8: VEROMOS | B8: Bearman(water) | C8: Y | D8: 4* 30
A9: VEROMOS | B9: G.reapen(water) | C9: Y | D9: 4* 30
A10: VEROMOS | B10: Inferno(wind) | C10: Y | D10: 4* 30
A11: VEROMOS | B11: Imp(fire) | C11: Y | D11: 4* 30
A12: VEROMOS | B12: Succubus(fire) | C12: Y | D12: 5* 35
A13: VEROMOS | B13: Beast Hunter(fire) | C13: Y | D13: 4* 30
A14: VEROMOS | B14: Salamander(fire) | C14: Y | D14: 4* 30
A15: VEROMOS | B15: Harpy(water) | C15: Y | D15: 4* 30
A16: VEROMOS | B16: Harpu(wind) | C16: Y | D16: 4* 30
A17: VEROMOS | B17: Vampire(wind) | C17: Y | D17: 5* 35
A18: VEROMOS | B18: Lizardman(wind) | C18: Y | D18: 4* 30
A19: VEROMOS | B19: Minotaur(wind) | C19: Y | D19: 4* 30
... A21: VEROMOS | B21: Pixie(water) | C21: Y | D21: 4* 30
A22: VEROMOS | B22: Yeti(dark) | D22: 5*35
A23: VEROMOS | B23: Veromos | C23: Y | D23: 6* 39 | P23: 5 | Q23: 15 | S23: 10 | T23: 20
E24: Tot. Need | F24: =SUM(F$7:F$23) -> 0 | G24: =SUM(G$7:G$23) -> 0 | H24: =SUM(H$7:H$23) -> 0 | I24: =SUM(I$7:I$23) -> 0 | J24: =SUM(J$7:J$23) -> 0 | K24: =SUM(K$7:K$23) -> 0 | L24: =SUM(L$7:L$23) -> 0 | M24: =SUM(M$7:M$23) -> 0 | ... T24: =SUM(T$7:T$23) -> 20
E25: Tot.got
E26: Missing | F26: =MAXA(F24-F25,0) -> 0 | G26: =MAXA(G24-G25,0) -> 0 | H26: =MAXA(H24-H25,0) -> 0 | I26: =MAXA(I24-I25,0) -> 0 | J26: =MAXA(J24-J25,0) -> 0 | K26: =MAXA(K24-K25,0) -> 0 | L26: =MAXA(L24-L25,0) -> 0 | M26: =MAXA(M24-M25,0) -> 0 | ... T26: =MAXA(T24-T25,0) -> 20
G27: Runs number to finish
E28: 9 | F28: =F$26/VLOOKUP(F$6,Tabela11[#All],6,FALSE) -> 0 | G28: =G$26/VLOOKUP(G$6,Tabela11[#All],6,FALSE) -> 0 | H28: =H$26/VLOOKUP(H$6,Tabela11[#All],6,FALSE) -> 0 | I28: =I$26/VLOOKUP(I$6,Tabela11[#All],6,FALSE) -> 0 | J28: =J$26/VLOOKUP(J$6,Tabela11[#All],6,FALSE) -> 0 | K28: =K$26/VLOOKUP(K$6,Tabela11[#All],6,FALSE) -> 0 | L28: =L$26/VLOOKUP(L$6,Tabela11[#All],6,FALSE) -> 0 | M28: =M$26/VLOOKUP(M$6,Tabela11[#All],6,FALSE) -> 0 | ... T28: =T$26/VLOOKUP(T$6,Tabela11[#All],6,FALSE) -> 75
E29: 8 | F29: =F$26/VLOOKUP(F$6,Tabela11[#All],5,FALSE) -> 0 | G29: =G$26/VLOOKUP(G$6,Tabela11[#All],5,FALSE) -> 0 | H29: =H$26/VLOOKUP(H$6,Tabela11[#All],5,FALSE) -> 0 | I29: =I$26/VLOOKUP(I$6,Tabela11[#All],5,FALSE) -> 0 | J29: =J$26/VLOOKUP(J$6,Tabela11[#All],5,FALSE) -> 0 | K29: =K$26/VLOOKUP(K$6,Tabela11[#All],5,FALSE) -> 0 | L29: =L$26/VLOOKUP(L$6,Tabela11[#All],5,FALSE) -> 0 | M29: =M$26/VLOOKUP(M$6,Tabela11[#All],5,FALSE) -> 0 | ... T29: =T$26/VLOOKUP(T$6,Tabela11[#All],5,FALSE) -> 91.428571
E30: 7 | F30: =F$26/VLOOKUP(F$6,Tabela11[#All],4,FALSE) -> 0 | G30: =G$26/VLOOKUP(G$6,Tabela11[#All],4,FALSE) -> 0 | H30: =H$26/VLOOKUP(H$6,Tabela11[#All],4,FALSE) -> 0 | I30: =I$26/VLOOKUP(I$6,Tabela11[#All],4,FALSE) -> 0 | J30: =J$26/VLOOKUP(J$6,Tabela11[#All],4,FALSE) -> 0 | K30: =K$26/VLOOKUP(K$6,Tabela11[#All],4,FALSE) -> 0 | L30: =L$26/VLOOKUP(L$6,Tabela11[#All],4,FALSE) -> 0 | M30: =M$26/VLOOKUP(M$6,Tabela11[#All],4,FALSE) -> 0 | ... T30: =T$26/VLOOKUP(T$6,Tabela11[#All],4,FALSE) -> 148.88889
G32: Energy cost | U32: Total Energy Req
E33: 9 | F33: =F$26/VLOOKUP(F$6,Tabela11[#All],6,FALSE)*(7-12*0.065) -> 0 | G33: =G$26/VLOOKUP(G$6,Tabela11[#All],6,FALSE)*(7-12*0.065) -> 0 | H33: =H$26/VLOOKUP(H$6,Tabela11[#All],6,FALSE)*(7-12*0.065) -> 0 | I33: =I$26/VLOOKUP(I$6,Tabela11[#All],6,FALSE)*(7-12*0.065) -> 0 | J33: =J$26/VLOOKUP(J$6,Tabela11[#All],6,FALSE)*(7-12*0.065) -> 0 | K33: =K$26/VLOOKUP(K$6,Tabela11[#All],6,FALSE)*(7-12*0.065) -> 0 | L33: =L$26/VLOOKUP(L$6,Tabela11[#All],6,FALSE)*(7-12*0.065) -> 0 | M33: =M$26/VLOOKUP(M$6,Tabela11[#All],6,FALSE)*(7-12*0.065) -> 0 | ... T33: =T$26/VLOOKUP(T$6,Tabela11[#All],6,FALSE)*(7-12*0.065) -> 466.5 | U33: =MAX(F33:H33)+MAX(I33:K33)+MAX(L33:N33)+MAX(O33:Q33)+MAX(R33:T33) -> 816.375
E34: 8 | F34: =F$26/VLOOKUP(F$6,Tabela11[#All],5,FALSE)*(7-12*0.065) -> 0 | G34: =G$26/VLOOKUP(G$6,Tabela11[#All],5,FALSE)*(7-12*0.065) -> 0 | H34: =H$26/VLOOKUP(H$6,Tabela11[#All],5,FALSE)*(7-12*0.065) -> 0 | I34: =I$26/VLOOKUP(I$6,Tabela11[#All],5,FALSE)*(7-12*0.065) -> 0 | J34: =J$26/VLOOKUP(J$6,Tabela11[#All],5,FALSE)*(7-12*0.065) -> 0 | K34: =K$26/VLOOKUP(K$6,Tabela11[#All],5,FALSE)*(7-12*0.065) -> 0 | L34: =L$26/VLOOKUP(L$6,Tabela11[#All],5,FALSE)*(7-12*0.065) -> 0 | M34: =M$26/VLOOKUP(M$6,Tabela11[#All],5,FALSE)*(7-12*0.065) -> 0 | ... T34: =T$26/VLOOKUP(T$6,Tabela11[#All],5,FALSE)*(7-12*0.065) -> 568.68571 | U34: =MAX(F34:H34)+MAX(I34:K34)+MAX(L34:N34)+MAX(O34:Q34)+MAX(R34:T34) -> 995.2
E35: 7 | F35: =F$26/VLOOKUP(F$6,Tabela11[#All],4,FALSE)*(6-12*0.065) -> 0 | G35: =G$26/VLOOKUP(G$6,Tabela11[#All],4,FALSE)*(6-12*0.065) -> 0 | H35: =H$26/VLOOKUP(H$6,Tabela11[#All],4,FALSE)*(6-12*0.065) -> 0 | I35: =I$26/VLOOKUP(I$6,Tabela11[#All],4,FALSE)*(6-12*0.065) -> 0 | J35: =J$26/VLOOKUP(J$6,Tabela11[#All],4,FALSE)*(6-12*0.065) -> 0 | K35: =K$26/VLOOKUP(K$6,Tabela11[#All],4,FALSE)*(6-12*0.065) -> 0 | L35: =L$26/VLOOKUP(L$6,Tabela11[#All],4,FALSE)*(6-12*0.065) -> 0 | M35: =M$26/VLOOKUP(M$6,Tabela11[#All],4,FALSE)*(6-12*0.065) -> 0 | ... T35: =T$26/VLOOKUP(T$6,Tabela11[#All],4,FALSE)*(6-12*0.065) -> 777.2 | U35: =MAX(F35:H35)+MAX(I35:K35)+MAX(L35:N35)+MAX(O35:Q35)+MAX(R35:T35) -> 1360.1
F37: Water | I37: Wind | L37: Fire | O37: Magic | R37: Dark
C38: GOT | D38: Grade/lvl | F38: Low | G38: Mid | H38: High | I38: Low | J38: Mid | K38: High | L38: Low | M38: Mid | N38: High | O38: Low | P38: Mid | Q38: High | R38: Low | S38: Mid | T38: High
A39: SIGMARUS | B39: Joker(fire) | M39: 20 | N39: 10 | P39: 15 | Q39: 5
A40: SIGMARUS | B40: Werewolf(fire) | C40: 1 | L40: 10 | M40: 15 | O40: 5 | P40: 10
A41: SIGMARUS | B41: M.Archer(fire) | C41: 2 | L41: 5 | M41: 20 | O41: 5 | P41: 15
A42: SIGMARUS | B42: Golem(water) | C42: 1 | F42: 10 | G42: 15 | O42: 5 | P42: 10
A43: SIGMARUS | B43: Howl(wind) | C43: 1 | I43: 20 | O43: 15
A44: SIGMARUS | B44: Ninja(water) | G44: 20 | H44: 10 | P44: 15 | Q44: 5
A45: SIGMARUS | B45: Inugami(water) | C45: 1 | F45: 10 | G45: 15 | O45: 5 | P45: 10
A46: SIGMARUS | B46: Griffon(water) | C46: 1 | F46: 10 | G46: 15 | O46: 5 | P46: 10
A47: SIGMARUS | B47: Bearman(wind) | C47: 1 | I47: 10 | J47: 15 | O47: 5 | P47: 10
...

Sheet Location features
A1: Location | B1: LVL | C1: Stage | D1: E. Cost | E1: XP Gain per member | F1: Mon nbr | G1: Uwagi | H1: Soloable | I1: Drop worth gain | J1: Energy gain | K1: XP Total Gain | L1: XP Train Gain | M1: XP drop | N1: DropWorthGain/Energy | O1: XP train/energy | P1: XP/Energy | Q1: Próbka | R1: Pure Cash to XP + XP Train/Energy | S1: TimeToComplete Sek | T1: SetToComplete | U1: TimeToComplete Sek2 | V1: SetToComplete2
A2: Aiden | B2: Hard | C2: 11 | D2: 4 | E2: 1394 | F2: 13 | I2: =AVERAGEIFS(DropAnalityka[Mana drop],DropAnalityka[Location],LocFeatures[[#This Row],[Location]],DropAnalityka[LVL],LocFeatures[[#This Row],[LVL]],DropAnalityka[Stage],LocFeatures[[#This Row],[Stage]])+AVERAGEIFS(DropAnalityka[Drop Worth],DropAnalityka[Location],LocFeatures[[#This Row],[Location]],DropAnalityka[LVL],LocFeatures[[#This Row],[LVL]],DropAnalityka[Stage],LocFeatures[[#This Row],[Stage]])+AVERAGEIFS(DropAnalityka[Fod Worth],DropAnalityka[Location],LocFeatures[[#This Row],[Location]],DropAnalityka[LVL],LocFeatures[[#This Row],[LVL]],DropAnalityka[Stage],LocFeatures[[#This Row],[Stage]]) -> 4948.25 | J2: =AVERAGEIFS(DropAnalityka[Energy Drop],DropAnalityka[Location],LocFeatures[[#This Row],[Location]],DropAnalityka[LVL],LocFeatures[[#This Row],[LVL]],DropAnalityka[Stage],LocFeatures[[#This Row],[Stage]]) -> 0.78125 | K2: =4*LocFeatures[[#This Row],[XP Gain per member]] -> 5576 | L2: =3*LocFeatures[[#This Row],[XP Gain per member]] -> 4182 | M2: =AVERAGEIFS(DropAnalityka[Exp Gain],DropAnalityka[Location],LocFeatures[[#This Row],[Location]],DropAnalityka[LVL],LocFeatures[[#This Row],[LVL]],DropAnalityka[Stage],LocFeatures[[#This Row],[Stage]]) -> 1519.4375 | N2: =LocFeatures[[#This Row],[Drop worth gain]]/(LocFeatures[[#This Row],[E. Cost]]-LocFeatures[[#This Row],[Energy gain]]) -> 1537.3204 | O2: =LocFeatures[[#This Row],[XP Train Gain]]/(LocFeatures[[#This Row],[E. Cost]]-LocFeatures[[#This Row],[Energy gain]]) -> 1299.2621 | P2: =(LocFeatures[[#This Row],[XP Train Gain]]+LocFeatures[[#This Row],[XP drop]])/(LocFeatures[[#This Row],[E. Cost]]-LocFeatures[[#This Row],[Energy gain]]) -> 1771.3204 | Q2: =COUNTIFS(DropAnalityka[Location],LocFeatures[[#This Row],[Location]],DropAnalityka[LVL],LocFeatures[[#This Row],[LVL]],DropAnalityka[Stage],LocFeatures[[#This Row],[Stage]]) -> 32 | R2: =((AVERAGEIFS(DropAnalityka[Mana drop],DropAnalityka[Location],LocFeatures[[#This Row],[Location]],DropAnalityka[LVL],LocFeatures[[#This Row],[LVL]],DropAnalityka[Stage],LocFeatures[[#This Row],[Stage]])+AVERAGEIFS(DropAnalityka[Sell Drop],DropAnalityka[Location],LocFeatures[[#This Row],[Location]],DropAnalityka[LVL],LocFeatures[[#This Row],[LVL]],DropAnalityka[Stage],LocFeatures[[#This Row],[Stage]]))/(LocFeatures[[#This Row],[E. Cost]]-LocFeatures[[#This Row],[Energy gain]]))*3.4+LocFeatures[[#This Row],[XP train/energy]] -> 4821.8646
A3: Aiden | B3: Normal | C3: 1 | D3: 3 | E3: 799 | F3: 13 | I3: =AVERAGEIFS(DropAnalityka[Mana drop],DropAnalityka[Location],LocFeatures[[#This Row],[Location]],DropAnalityka[LVL],LocFeatures[[#This Row],[LVL]],DropAnalityka[Stage],LocFeatures[[#This Row],[Stage]])+AVERAGEIFS(DropAnalityka[Drop Worth],DropAnalityka[Location],LocFeatures[[#This Row],[Location]],DropAnalityka[LVL],LocFeatures[[#This Row],[LVL]],DropAnalityka[Stage],LocFeatures[[#This Row],[Stage]])+AVERAGEIFS(DropAnalityka[Fod Worth],DropAnalityka[Location],LocFeatures[[#This Row],[Location]],DropAnalityka[LVL],LocFeatures[[#This Row],[LVL]],DropAnalityka[Stage],LocFeatures[[#This Row],[Stage]]) -> 3789.9479 | J3: =AVERAGEIFS(DropAnalityka[Energy Drop],DropAnalityka[Location],LocFeatures[[#This Row],[Location]],DropAnalityka[LVL],LocFeatures[[#This Row],[LVL]],DropAnalityka[Stage],LocFeatures[[#This Row],[Stage]]) -> 0.88541667 | K3: =4*LocFeatures[[#This Row],[XP Gain per member]] -> 3196 | L3: =3*LocFeatures[[#This Row],[XP Gain per member]] -> 2397 | M3: =AVERAGEIFS(DropAnalityka[Exp Gain],DropAnalityka[Location],LocFeatures[[#This Row],[Location]],DropAnalityka[LVL],LocFeatures[[#This Row],[LVL]],DropAnalityka[Stage],LocFeatures[[#This Row],[Stage]]) -> 175 | N3: =LocFeatures[[#This Row],[Drop worth gain]]/(LocFeatures[[#This Row],[E. Cost]]-LocFeatures[[#This Row],[Energy gain]]) -> 1792.2906 | O3: =LocFeatures[[#This Row],[XP Train Gain]]/(LocFeatures[[#This Row],[E. Cost]]-LocFeatures[[#This Row],[Energy gain]]) -> 1133.5567 | P3: =(LocFeatures[[#This Row],[XP Train Gain]]+LocFeatures[[#This Row],[XP drop]])/(LocFeatures[[#This Row],[E. Cost]]-LocFeatures[[#This Row],[Energy gain]]) -> 1216.3153 | Q3: =COUNTIFS(DropAnalityka[Location],LocFeatures[[#This Row],[Location]],DropAnalityka[LVL],LocFeatures[[#This Row],[LVL]],DropAnalityka[Stage],LocFeatures[[#This Row],[Stage]]) -> 96 | R3: =((AVERAGEIFS(DropAnalityka[Mana drop],DropAnalityka[Location],LocFeatures[[#This Row],[Location]],DropAnalityka[LVL],LocFeatures[[#This Row],[LVL]],DropAnalityka[Stage],LocFeatures[[#This Row],[Stage]])+AVERAGEIFS(DropAnalityka[Sell Drop],DropAnalityka[Location],LocFeatures[[#This Row],[Location]],DropAnalityka[LVL],LocFeatures[[#This Row],[LVL]],DropAnalityka[Stage],LocFeatures[[#This Row],[Stage]]))/(LocFeatures[[#This Row],[E. Cost]]-LocFeatures[[#This Row],[Energy gain]]))*3.4+LocFeatures[[#This Row],[XP train/energy]] -> 4790.399
A4: Aiden | B4: Normal | C4: 2 | D4: 3 | E4: 804 | F4: 13 | I4: =AVERAGEIFS(DropAnalityka[Mana drop],DropAnalityka[Location],LocFeatures[[#This Row],[Location]],DropAnalityka[LVL],LocFeatures[[#This Row],[LVL]],DropAnalityka[Stage],LocFeatures[[#This Row],[Stage]])+AVERAGEIFS(DropAnalityka[Drop Worth],DropAnalityka[Location],LocFeatures[[#This Row],[Location]],DropAnalityka[LVL],LocFeatures[[#This Row],[LVL]],DropAnalityka[Stage],LocFeatures[[#This Row],[Stage]])+AVERAGEIFS(DropAnalityka[Fod Worth],DropAnalityka[Location],LocFeatures[[#This Row],[Location]],DropAnalityka[LVL],LocFeatures[[#This Row],[LVL]],DropAnalityka[Stage],LocFeatures[[#This Row],[Stage]]) -> 3392 | J4: =AVERAGEIFS(DropAnalityka[Energy Drop],DropAnalityka[Location],LocFeatures[[#This Row],[Location]],DropAnalityka[LVL],LocFeatures[[#This Row],[LVL]],DropAnalityka[Stage],LocFeatures[[#This Row],[Stage]]) -> 0 | K4: =4*LocFeatures[[#This Row],[XP Gain per member]] -> 3216 | L4: =3*LocFeatures[[#This Row],[XP Gain per member]] -> 2412 | M4: =AVERAGEIFS(DropAnalityka[Exp Gain],DropAnalityka[Location],LocFeatures[[#This Row],[Location]],DropAnalityka[LVL],LocFeatures[[#This Row],[LVL]],DropAnalityka[Stage],LocFeatures[[#This Row],[Stage]]) -> 0 | N4: =LocFeatures[[#This Row],[Drop worth gain]]/(LocFeatures[[#This Row],[E. Cost]]-LocFeatures[[#This Row],[Energy gain]]) -> 1130.6667 | O4: =LocFeatures[[#This Row],[XP Train Gain]]/(LocFeatures[[#This Row],[E. Cost]]-LocFeatures[[#This Row],[Energy gain]]) -> 804 | P4: =(LocFeatures[[#This Row],[XP Train Gain]]+LocFeatures[[#This Row],[XP drop]])/(LocFeatures[[#This Row],[E. Cost]]-LocFeatures[[#This Row],[Energy gain]]) -> 804 | Q4: =COUNTIFS(DropAnalityka[Location],LocFeatures[[#This Row],[Location]],DropAnalityka[LVL],LocFeatures[[#This Row],[LVL]],DropAnalityka[Stage],LocFeatures[[#This Row],[Stage]]) -> 1 | R4: =((AVERAGEIFS(DropAnalityka[Mana drop],DropAnalityka[Location],LocFeatures[[#This Row],[Location]],DropAnalityka[LVL],LocFeatures[[#This Row],[LVL]],DropAnalityka[Stage],LocFeatures[[#This Row],[Stage]])+AVERAGEIFS(DropAnalityka[Sell Drop],DropAnalityka[Location],LocFeatures[[#This Row],[Location]],DropAnalityka[LVL],LocFeatures[[#This Row],[LVL]],DropAnalityka[Stage],LocFeatures[[#This Row],[Stage]]))/(LocFeatures[[#This Row],[E. Cost]]-LocFeatures[[#This Row],[Energy gain]]))*3.4+LocFeatures[[#This Row],[XP train/energy]] -> 4648.2667
A5: Aiden | B5: Normal | C5: 3 | D5: 3 | E5: 804 | I5: =AVERAGEIFS(DropAnalityka[Mana drop],DropAnalityka[Location],LocFeatures[[#This Row],[Location]],DropAnalityka[LVL],LocFeatures[[#This Row],[LVL]],DropAnalityka[Stage],LocFeatures[[#This Row],[Stage]])+AVERAGEIFS(DropAnalityka[Drop Worth],DropAnalityka[Location],LocFeatures[[#This Row],[Location]],DropAnalityka[LVL],LocFeatures[[#This Row],[LVL]],DropAnalityka[Stage],LocFeatures[[#This Row],[Stage]])+AVERAGEIFS(DropAnalityka[Fod Worth],DropAnalityka[Location],LocFeatures[[#This Row],[Location]],DropAnalityka[LVL],LocFeatures[[#This Row],[LVL]],DropAnalityka[Stage],LocFeatures[[#This Row],[Stage]]) -> 2964 | J5: =AVERAGEIFS(DropAnalityka[Energy Drop],DropAnalityka[Location],LocFeatures[[#This Row],[Location]],DropAnalityka[LVL],LocFeatures[[#This Row],[LVL]],DropAnalityka[Stage],LocFeatures[[#This Row],[Stage]]) -> 0 | K5: =4*LocFeatures[[#This Row],[XP Gain per member]] -> 3216 | L5: =3*LocFeatures[[#This Row],[XP Gain per member]] -> 2412 | M5: =AVERAGEIFS(DropAnalityka[Exp Gain],DropAnalityka[Location],LocFeatures[[#This Row],[Location]],DropAnalityka[LVL],LocFeatures[[#This Row],[LVL]],DropAnalityka[Stage],LocFeatures[[#This Row],[Stage]]) -> 0 | N5: =LocFeatures[[#This Row],[Drop worth gain]]/(LocFeatures[[#This Row],[E. Cost]]-LocFeatures[[#This Row],[Energy gain]]) -> 988 | O5: =LocFeatures[[#This Row],[XP Train Gain]]/(LocFeatures[[#This Row],[E. Cost]]-LocFeatures[[#This Row],[Energy gain]]) -> 804 | P5: =(LocFeatures[[#This Row],[XP Train Gain]]+LocFeatures[[#This Row],[XP drop]])/(LocFeatures[[#This Row],[E. Cost]]-LocFeatures[[#This Row],[Energy gain]]) -> 804 | Q5: =COUNTIFS(DropAnalityka[Location],LocFeatures[[#This Row],[Location]],DropAnalityka[LVL],LocFeatures[[#This Row],[LVL]],DropAnalityka[Stage],LocFeatures[[#This Row],[Stage]]) -> 2 | R5: =((AVERAGEIFS(DropAnalityka[Mana drop],DropAnalityka[Location],LocFeatures[[#This Row],[Location]],DropAnalityka[LVL],LocFeatures[[#This Row],[LVL]],DropAnalityka[Stage],LocFeatures[[#This Row],[Stage]])+AVERAGEIFS(DropAnalityka[Sell Drop],DropAnalityka[Location],LocFeatures[[#This Row],[Location]],DropAnalityka[LVL],LocFeatures[[#This Row],[LVL]],DropAnalityka[Stage],LocFeatures[[#This Row],[Stage]]))/(LocFeatures[[#This Row],[E. Cost]]-LocFeatures[[#This Row],[Energy gain]]))*3.4+LocFeatures[[#This Row],[XP train/energy]] -> 4163.2
A6: Dragon | B6: Normal | C6: 8 | D6: 8 | I6: =AVERAGEIFS(DropAnalityka[Mana drop],DropAnalityka[Location],LocFeatures[[#This Row],[Location]],DropAnalityka[LVL],LocFeatures[[#This Row],[LVL]],DropAnalityka[Stage],LocFeatures[[#This Row],[Stage]])+AVERAGEIFS(DropAnalityka[Drop Worth],DropAnalityka[Location],LocFeatures[[#This Row],[Location]],DropAnalityka[LVL],LocFeatures[[#This Row],[LVL]],DropAnalityka[Stage],LocFeatures[[#This Row],[Stage]])+AVERAGEIFS(DropAnalityka[Fod Worth],DropAnalityka[Location],LocFeatures[[#This Row],[Location]],DropAnalityka[LVL],LocFeatures[[#This Row],[LVL]],DropAnalityka[Stage],LocFeatures[[#This Row],[Stage]]) -> 12029.389 | J6: =AVERAGEIFS(DropAnalityka[Energy Drop],DropAnalityka[Location],LocFeatures[[#This Row],[Location]],DropAnalityka[LVL],LocFeatures[[#This Row],[LVL]],DropAnalityka[Stage],LocFeatures[[#This Row],[Stage]]) -> 0.88888889 | K6: =5*LocFeatures[[#This Row],[XP Gain per member]] -> 0 | L6: =3*LocFeatures[[#This Row],[XP Gain per member]] -> 0 | M6: =AVERAGEIFS(DropAnalityka[Exp Gain],DropAnalityka[Location],LocFeatures[[#This Row],[Location]],DropAnalityka[LVL],LocFeatures[[#This Row],[LVL]],DropAnalityka[Stage],LocFeatures[[#This Row],[Stage]]) -> 3190.1111 | N6: =LocFeatures[[#This Row],[Drop worth gain]]/(LocFeatures[[#This Row],[E. Cost]]-LocFeatures[[#This Row],[Energy gain]]) -> 1691.6328 | O6: =LocFeatures[[#This Row],[XP Train Gain]]/(LocFeatures[[#This Row],[E. Cost]]-LocFeatures[[#This Row],[Energy gain]]) -> 0 | P6: =(LocFeatures[[#This Row],[XP Train Gain]]+LocFeatures[[#This Row],[XP drop]])/(LocFeatures[[#This Row],[E. Cost]]-LocFeatures[[#This Row],[Energy gain]]) -> 448.60938 | Q6: =COUNTIFS(DropAnalityka[Location],LocFeatures[[#This Row],[Location]],DropAnalityka[LVL],LocFeatures[[#This Row],[LVL]],DropAnalityka[Stage],LocFeatures[[#This Row],[Stage]]) -> 18 | R6: =((AVERAGEIFS(DropAnalityka[Mana drop],DropAnalityka[Location],LocFeatures[[#This Row],[Location]],DropAnalityka[LVL],LocFeatures[[#This Row],[LVL]],DropAnalityka[Stage],LocFeatures[[#This Row],[Stage]])+AVERAGEIFS(DropAnalityka[Sell Drop],DropAnalityka[Location],LocFeatures[[#This Row],[Location]],DropAnalityka[LVL],LocFeatures[[#This Row],[LVL]],DropAnalityka[Stage],LocFeatures[[#This Row],[Stage]]))/(LocFeatures[[#This Row],[E. Cost]]-LocFeatures[[#This Row],[Energy gain]]))*3.4+LocFeatures[[#This Row],[XP train/energy]] -> 4138.1141
